[W&B] Initialized run data2_multi_mpc_e52-75

******************************************************************************
This program contains Ipopt, a library for large-scale nonlinear optimization.
 Ipopt is released as open source code under the Eclipse Public License (EPL).
         For more information visit https://github.com/coin-or/Ipopt
******************************************************************************

Collision detected 65.75397 65.96709 0.6416295 0.75495636
Collision detected 65.92683 66.02543 0.66059947 0.74788225
Collision detected 66.02064 66.07257 0.66873515 0.7407182
Collision detected 66.04898 66.117935 0.67231023 0.7347398
Collision detected 66.07225 66.15795 0.6741451 0.72933257
Collision detected 66.09445 66.19214 0.67504835 0.7236417
Collision detected 66.116806 66.23049 0.6755531 0.7175358
Collision detected 66.13946 66.269585 0.6752515 0.7114877
Collision detected 66.16251 66.307594 0.67427427 0.704804
Collision detected 66.18226 66.3493 0.6725769 0.6974762
Collision detected 66.20655 66.392845 0.6701929 0.689695
Collision detected 66.231766 66.43682 0.66716075 0.6812015
Collision detected 66.25822 66.48548 0.66381 0.6716803
Collision detected 66.28634 66.53771 0.6595309 0.66123843
Collision detected 66.31475 66.59285 0.6542577 0.64929694
Collision detected 66.34852 66.65582 0.64777863 0.6353418
Collision detected 66.38729 66.72556 0.63978976 0.61867505
Ego progress:  131.3527069091797
Opp1 progress:  138.49806213378906
Opp2 progress:  3.8744261264801025
[Episode 52] Uploaded directly to W&B (in-memory). Steps: 500
[Seed] Global seed set to 1756272091
[Episode 53] Using seed 1756272091
ep_no: 53
ego params:  0.2 0.2 0.24 1.0
opp params:  0.1 0.5 0.15 1.0
opp1 params: 0.36937922259743317 0.49787376936699623 0.348000147067956 1.0020386384406574
Ego progress:  139.82159423828125
Opp1 progress:  138.6206512451172
Opp2 progress:  130.68397521972656
[Episode 53] Uploaded directly to W&B (in-memory). Steps: 500
[Seed] Global seed set to 1756272092
[Episode 54] Using seed 1756272092
ep_no: 54
ego params:  0.35747729258959404 0.4838264578743069 0.15728543090047362 1.0032016430586495
opp params:  0.1 0.5 0.15 1.0
opp1 params: 0.36937922259743317 0.49787376936699623 0.348000147067956 1.0020386384406574
Collision detected 65.67737 65.54446 0.75161415 0.6244437
Collision detected 65.73674 65.74303 0.7442016 0.66974527
Collision detected 65.78 65.80516 0.7384031 0.68395674
Collision detected 65.79893 65.85775 0.7355733 0.6919258
Collision detected 65.81947 65.901024 0.7327964 0.69689703
Collision detected 65.84004 65.9324 0.72983325 0.69904655
Collision detected 65.86074 65.97147 0.72740525 0.6991515
Collision detected 65.88158 66.01052 0.72465676 0.69869244
Collision detected 65.90261 66.04362 0.7217178 0.6966354
Collision detected 65.91513 66.08402 0.718428 0.6930097
Collision detected 65.93714 66.12589 0.7147251 0.688692
Collision detected 65.95996 66.16978 0.7106861 0.6832173
Collision detected 65.983986 66.21252 0.70664996 0.67616934
Collision detected 66.0096 66.26265 0.702175 0.66804034
Collision detected 66.03734 66.31516 0.69712865 0.65820605
Collision detected 66.06214 66.37558 0.6907847 0.64624864
Collision detected 66.098015 66.44218 0.68303096 0.6318366
Ego progress:  148.90878295898438
Opp1 progress:  128.39405822753906
Opp2 progress:  129.59915161132812
[Episode 54] Uploaded directly to W&B (in-memory). Steps: 500
[Seed] Global seed set to 1756272093
[Episode 55] Using seed 1756272093
ep_no: 55
ego params:  0.35747729258959404 0.4838264578743069 0.15728543090047362 1.0032016430586495
opp params:  0.3621859204634289 0.35242731584611153 0.31827597372190036 1.0152227022468843
opp1 params: 0.36937922259743317 0.49787376936699623 0.348000147067956 1.0020386384406574
CasADi - 2025-08-27 11:06:36 WARNING("KeyboardInterruptException") [.../casadi/interfaces/ipopt/ipopt_nlp.cpp:132]
Error in callback:  <built-in function Function_call> returned a result with an exception set
KeyboardInterrupt

The above exception was the direct cause of the following exception:

Traceback (most recent call last):
  File "/home/mahin-sanklecha/.local/lib/python3.10/site-packages/casadi/casadi.py", line 9331, in <lambda>
    __setattr__ = lambda self, name, value: _swig_setattr(self, DM, name, value)
  File "/home/mahin-sanklecha/.local/lib/python3.10/site-packages/casadi/casadi.py", line 74, in _swig_setattr
    return _swig_setattr_nondynamic(self, class_type, name, value, 0)
  File "/home/mahin-sanklecha/.local/lib/python3.10/site-packages/casadi/casadi.py", line 58, in _swig_setattr_nondynamic
    if type(value).__name__ == 'SwigPyObject':
SystemError: <class 'type'> returned a result with an exception set

The above exception was the direct cause of the following exception:

Traceback (most recent call last):
  File "/home/mahin-sanklecha/.local/lib/python3.10/site-packages/casadi/casadi.py", line 9331, in <lambda>
    __setattr__ = lambda self, name, value: _swig_setattr(self, DM, name, value)
  File "/home/mahin-sanklecha/.local/lib/python3.10/site-packages/casadi/casadi.py", line 74, in _swig_setattr
    return _swig_setattr_nondynamic(self, class_type, name, value, 0)
  File "/home/mahin-sanklecha/.local/lib/python3.10/site-packages/casadi/casadi.py", line 58, in _swig_setattr_nondynamic
    if type(value).__name__ == 'SwigPyObject':
SystemError: <class 'type'> returned a result with an exception set

The above exception was the direct cause of the following exception:

Traceback (most recent call last):
  File "/home/mahin-sanklecha/.local/lib/python3.10/site-packages/casadi/casadi.py", line 9331, in <lambda>
    __setattr__ = lambda self, name, value: _swig_setattr(self, DM, name, value)
  File "/home/mahin-sanklecha/.local/lib/python3.10/site-packages/casadi/casadi.py", line 74, in _swig_setattr
    return _swig_setattr_nondynamic(self, class_type, name, value, 0)
  File "/home/mahin-sanklecha/.local/lib/python3.10/site-packages/casadi/casadi.py", line 58, in _swig_setattr_nondynamic
    if type(value).__name__ == 'SwigPyObject':
SystemError: <class 'type'> returned a result with an exception set

The above exception was the direct cause of the following exception:

Traceback (most recent call last):
  File "/home/mahin-sanklecha/.local/lib/python3.10/site-packages/casadi/casadi.py", line 9331, in <lambda>
    __setattr__ = lambda self, name, value: _swig_setattr(self, DM, name, value)
  File "/home/mahin-sanklecha/.local/lib/python3.10/site-packages/casadi/casadi.py", line 74, in _swig_setattr
    return _swig_setattr_nondynamic(self, class_type, name, value, 0)
  File "/home/mahin-sanklecha/.local/lib/python3.10/site-packages/casadi/casadi.py", line 58, in _swig_setattr_nondynamic
    if type(value).__name__ == 'SwigPyObject':
SystemError: <class 'type'> returned a result with an exception set

The above exception was the direct cause of the following exception:

Traceback (most recent call last):
  File "/home/mahin-sanklecha/.local/lib/python3.10/site-packages/casadi/casadi.py", line 9331, in <lambda>
    __setattr__ = lambda self, name, value: _swig_setattr(self, DM, name, value)
  File "/home/mahin-sanklecha/.local/lib/python3.10/site-packages/casadi/casadi.py", line 74, in _swig_setattr
    return _swig_setattr_nondynamic(self, class_type, name, value, 0)
  File "/home/mahin-sanklecha/.local/lib/python3.10/site-packages/casadi/casadi.py", line 58, in _swig_setattr_nondynamic
    if type(value).__name__ == 'SwigPyObject':
SystemError: <class 'type'> returned a result with an exception set

The above exception was the direct cause of the following exception:

Traceback (most recent call last):
  File "/home/mahin-sanklecha/.local/lib/python3.10/site-packages/casadi/casadi.py", line 9331, in <lambda>
    __setattr__ = lambda self, name, value: _swig_setattr(self, DM, name, value)
  File "/home/mahin-sanklecha/.local/lib/python3.10/site-packages/casadi/casadi.py", line 74, in _swig_setattr
    return _swig_setattr_nondynamic(self, class_type, name, value, 0)
  File "/home/mahin-sanklecha/.local/lib/python3.10/site-packages/casadi/casadi.py", line 58, in _swig_setattr_nondynamic
    if type(value).__name__ == 'SwigPyObject':
SystemError: <class 'type'> returned a result with an exception set

The above exception was the direct cause of the following exception:

Traceback (most recent call last):
  File "/home/mahin-sanklecha/alpha-RACER/car_ros2/car_ros2/multi_car_blocking.py", line 2538, in timer_callback
    steer, throttle, _, _, self.last_i_opp1 = self.mpc(
  File "/home/mahin-sanklecha/alpha-RACER/car_ros2/car_ros2/multi_car_blocking.py", line 2868, in mpc
    throttle, steer = mpc([x, y, theta, v], np.array(traj), lookahead_factor=lookahead_factor)
  File "/home/mahin-sanklecha/alpha-RACER/car_ros2/car_ros2/mpc_controller.py", line 95, in mpc
    solution = solver(x0=initial_guess, lbg=lbg, ubg=ubg, p=params)
  File "/home/mahin-sanklecha/.local/lib/python3.10/site-packages/casadi/casadi.py", line 24049, in __call__
    return self.call(kwargs)
  File "/home/mahin-sanklecha/.local/lib/python3.10/site-packages/casadi/casadi.py", line 20698, in call
    return _casadi.Function_call(self, *args)
SystemError: <built-in function Function_call> returned a result with an exception set

During handling of the above exception, another exception occurred:

Traceback (most recent call last):
  File "/home/mahin-sanklecha/alpha-RACER/car_ros2/car_ros2/multi_car_blocking.py", line 3018, in <module>
    main()
  File "/home/mahin-sanklecha/alpha-RACER/car_ros2/car_ros2/multi_car_blocking.py", line 3012, in main
    car_node.timer_callback()
  File "/home/mahin-sanklecha/alpha-RACER/car_ros2/car_ros2/multi_car_blocking.py", line 2743, in timer_callback
    self._save_and_upload_episode()
  File "/home/mahin-sanklecha/alpha-RACER/car_ros2/car_ros2/multi_car_blocking.py", line 2207, in _save_and_upload_episode
    success = upload_artifact_from_buffer(
  File "/home/mahin-sanklecha/alpha-RACER/car_ros2/car_ros2/multi_car_blocking.py", line 2056, in upload_artifact_from_buffer
    wandb.log_artifact(artifact)
  File "/home/mahin-sanklecha/.local/lib/python3.10/site-packages/wandb/sdk/wandb_run.py", line 399, in wrapper
    return func(self, *args, **kwargs)
  File "/home/mahin-sanklecha/.local/lib/python3.10/site-packages/wandb/sdk/wandb_run.py", line 457, in wrapper_fn
    return func(self, *args, **kwargs)
  File "/home/mahin-sanklecha/.local/lib/python3.10/site-packages/wandb/sdk/wandb_run.py", line 444, in wrapper
    return func(self, *args, **kwargs)
  File "/home/mahin-sanklecha/.local/lib/python3.10/site-packages/wandb/sdk/wandb_run.py", line 3159, in log_artifact
    return self._log_artifact(
  File "/home/mahin-sanklecha/.local/lib/python3.10/site-packages/wandb/sdk/wandb_run.py", line 3310, in _log_artifact
    self._assert_can_log_artifact(artifact)
  File "/home/mahin-sanklecha/.local/lib/python3.10/site-packages/wandb/sdk/wandb_run.py", line 3358, in _assert_can_log_artifact
    public_api = self._public_api()
  File "/home/mahin-sanklecha/.local/lib/python3.10/site-packages/wandb/sdk/wandb_run.py", line 3351, in _public_api
    return public.Api(overrides)
  File "/home/mahin-sanklecha/.local/lib/python3.10/site-packages/wandb/apis/public/api.py", line 352, in __init__
    self._configure_sentry()
  File "/home/mahin-sanklecha/.local/lib/python3.10/site-packages/wandb/apis/public/api.py", line 356, in _configure_sentry
    viewer = self.viewer
  File "/home/mahin-sanklecha/.local/lib/python3.10/site-packages/wandb/apis/public/api.py", line 780, in viewer
    viewer = self._client.execute(self.VIEWER_QUERY).get("viewer")
  File "/home/mahin-sanklecha/.local/lib/python3.10/site-packages/wandb/sdk/lib/retry.py", line 211, in wrapped_fn
    return retrier(*args, **kargs)
  File "/home/mahin-sanklecha/.local/lib/python3.10/site-packages/wandb/sdk/lib/retry.py", line 134, in __call__
    result = self._call_fn(*args, **kwargs)
  File "/home/mahin-sanklecha/.local/lib/python3.10/site-packages/wandb/apis/public/api.py", line 116, in execute
    return self._client.execute(*args, **kwargs)
  File "/home/mahin-sanklecha/.local/lib/python3.10/site-packages/wandb/vendor/gql-0.2.0/wandb_gql/client.py", line 52, in execute
    result = self._get_result(document, *args, **kwargs)
  File "/home/mahin-sanklecha/.local/lib/python3.10/site-packages/wandb/vendor/gql-0.2.0/wandb_gql/client.py", line 60, in _get_result
    return self.transport.execute(document, *args, **kwargs)
  File "/home/mahin-sanklecha/.local/lib/python3.10/site-packages/wandb/sdk/lib/gql_request.py", line 58, in execute
    request = self.session.post(self.url, **post_args)
  File "/home/mahin-sanklecha/.local/lib/python3.10/site-packages/requests/sessions.py", line 637, in post
    return self.request("POST", url, data=data, json=json, **kwargs)
  File "/home/mahin-sanklecha/.local/lib/python3.10/site-packages/requests/sessions.py", line 589, in request
    resp = self.send(prep, **send_kwargs)
  File "/home/mahin-sanklecha/.local/lib/python3.10/site-packages/requests/sessions.py", line 703, in send
    r = adapter.send(request, **kwargs)
  File "/home/mahin-sanklecha/.local/lib/python3.10/site-packages/requests/adapters.py", line 644, in send
    resp = conn.urlopen(
  File "/home/mahin-sanklecha/.local/lib/python3.10/site-packages/urllib3/connectionpool.py", line 787, in urlopen
    response = self._make_request(
  File "/home/mahin-sanklecha/.local/lib/python3.10/site-packages/urllib3/connectionpool.py", line 464, in _make_request
    self._validate_conn(conn)
  File "/home/mahin-sanklecha/.local/lib/python3.10/site-packages/urllib3/connectionpool.py", line 1093, in _validate_conn
    conn.connect()
  File "/home/mahin-sanklecha/.local/lib/python3.10/site-packages/urllib3/connection.py", line 753, in connect
    self.sock = sock = self._new_conn()
  File "/home/mahin-sanklecha/.local/lib/python3.10/site-packages/urllib3/connection.py", line 198, in _new_conn
    sock = connection.create_connection(
  File "/home/mahin-sanklecha/.local/lib/python3.10/site-packages/urllib3/util/connection.py", line 60, in create_connection
    for res in socket.getaddrinfo(host, port, family, socket.SOCK_STREAM):
  File "/usr/lib/python3.10/socket.py", line 955, in getaddrinfo
    for res in _socket.getaddrinfo(host, port, family, type, proto, flags):
KeyboardInterrupt
KeyboardInterrupt

The above exception was the direct cause of the following exception:

Traceback (most recent call last):
  File "/home/mahin-sanklecha/.local/lib/python3.10/site-packages/casadi/casadi.py", line 9331, in <lambda>
    __setattr__ = lambda self, name, value: _swig_setattr(self, DM, name, value)
  File "/home/mahin-sanklecha/.local/lib/python3.10/site-packages/casadi/casadi.py", line 74, in _swig_setattr
    return _swig_setattr_nondynamic(self, class_type, name, value, 0)
  File "/home/mahin-sanklecha/.local/lib/python3.10/site-packages/casadi/casadi.py", line 58, in _swig_setattr_nondynamic
    if type(value).__name__ == 'SwigPyObject':
SystemError: <class 'type'> returned a result with an exception set

The above exception was the direct cause of the following exception:

Traceback (most recent call last):
  File "/home/mahin-sanklecha/.local/lib/python3.10/site-packages/casadi/casadi.py", line 9331, in <lambda>
    __setattr__ = lambda self, name, value: _swig_setattr(self, DM, name, value)
  File "/home/mahin-sanklecha/.local/lib/python3.10/site-packages/casadi/casadi.py", line 74, in _swig_setattr
    return _swig_setattr_nondynamic(self, class_type, name, value, 0)
  File "/home/mahin-sanklecha/.local/lib/python3.10/site-packages/casadi/casadi.py", line 58, in _swig_setattr_nondynamic
    if type(value).__name__ == 'SwigPyObject':
SystemError: <class 'type'> returned a result with an exception set

The above exception was the direct cause of the following exception:

Traceback (most recent call last):
  File "/home/mahin-sanklecha/.local/lib/python3.10/site-packages/casadi/casadi.py", line 9331, in <lambda>
    __setattr__ = lambda self, name, value: _swig_setattr(self, DM, name, value)
  File "/home/mahin-sanklecha/.local/lib/python3.10/site-packages/casadi/casadi.py", line 74, in _swig_setattr
    return _swig_setattr_nondynamic(self, class_type, name, value, 0)
  File "/home/mahin-sanklecha/.local/lib/python3.10/site-packages/casadi/casadi.py", line 58, in _swig_setattr_nondynamic
    if type(value).__name__ == 'SwigPyObject':
SystemError: <class 'type'> returned a result with an exception set

The above exception was the direct cause of the following exception:

Traceback (most recent call last):
  File "/home/mahin-sanklecha/.local/lib/python3.10/site-packages/casadi/casadi.py", line 9331, in <lambda>
    __setattr__ = lambda self, name, value: _swig_setattr(self, DM, name, value)
  File "/home/mahin-sanklecha/.local/lib/python3.10/site-packages/casadi/casadi.py", line 74, in _swig_setattr
    return _swig_setattr_nondynamic(self, class_type, name, value, 0)
  File "/home/mahin-sanklecha/.local/lib/python3.10/site-packages/casadi/casadi.py", line 58, in _swig_setattr_nondynamic
    if type(value).__name__ == 'SwigPyObject':
SystemError: <class 'type'> returned a result with an exception set

The above exception was the direct cause of the following exception:

Traceback (most recent call last):
  File "/home/mahin-sanklecha/.local/lib/python3.10/site-packages/casadi/casadi.py", line 9331, in <lambda>
    __setattr__ = lambda self, name, value: _swig_setattr(self, DM, name, value)
  File "/home/mahin-sanklecha/.local/lib/python3.10/site-packages/casadi/casadi.py", line 74, in _swig_setattr
    return _swig_setattr_nondynamic(self, class_type, name, value, 0)
  File "/home/mahin-sanklecha/.local/lib/python3.10/site-packages/casadi/casadi.py", line 58, in _swig_setattr_nondynamic
    if type(value).__name__ == 'SwigPyObject':
SystemError: <class 'type'> returned a result with an exception set

The above exception was the direct cause of the following exception:

Traceback (most recent call last):
  File "/home/mahin-sanklecha/.local/lib/python3.10/site-packages/casadi/casadi.py", line 9331, in <lambda>
    __setattr__ = lambda self, name, value: _swig_setattr(self, DM, name, value)
  File "/home/mahin-sanklecha/.local/lib/python3.10/site-packages/casadi/casadi.py", line 74, in _swig_setattr
    return _swig_setattr_nondynamic(self, class_type, name, value, 0)
  File "/home/mahin-sanklecha/.local/lib/python3.10/site-packages/casadi/casadi.py", line 58, in _swig_setattr_nondynamic
    if type(value).__name__ == 'SwigPyObject':
SystemError: <class 'type'> returned a result with an exception set

The above exception was the direct cause of the following exception:

Traceback (most recent call last):
  File "/home/mahin-sanklecha/alpha-RACER/car_ros2/car_ros2/multi_car_blocking.py", line 2538, in timer_callback
    steer, throttle, _, _, self.last_i_opp1 = self.mpc(
  File "/home/mahin-sanklecha/alpha-RACER/car_ros2/car_ros2/multi_car_blocking.py", line 2868, in mpc
    throttle, steer = mpc([x, y, theta, v], np.array(traj), lookahead_factor=lookahead_factor)
  File "/home/mahin-sanklecha/alpha-RACER/car_ros2/car_ros2/mpc_controller.py", line 95, in mpc
    solution = solver(x0=initial_guess, lbg=lbg, ubg=ubg, p=params)
  File "/home/mahin-sanklecha/.local/lib/python3.10/site-packages/casadi/casadi.py", line 24049, in __call__
    return self.call(kwargs)
  File "/home/mahin-sanklecha/.local/lib/python3.10/site-packages/casadi/casadi.py", line 20698, in call
    return _casadi.Function_call(self, *args)
SystemError: <built-in function Function_call> returned a result with an exception set

During handling of the above exception, another exception occurred:

Traceback (most recent call last):
  File "/home/mahin-sanklecha/alpha-RACER/car_ros2/car_ros2/multi_car_blocking.py", line 3018, in <module>
    main()
  File "/home/mahin-sanklecha/alpha-RACER/car_ros2/car_ros2/multi_car_blocking.py", line 3012, in main
    car_node.timer_callback()
  File "/home/mahin-sanklecha/alpha-RACER/car_ros2/car_ros2/multi_car_blocking.py", line 2743, in timer_callback
    self._save_and_upload_episode()
  File "/home/mahin-sanklecha/alpha-RACER/car_ros2/car_ros2/multi_car_blocking.py", line 2207, in _save_and_upload_episode
    success = upload_artifact_from_buffer(
  File "/home/mahin-sanklecha/alpha-RACER/car_ros2/car_ros2/multi_car_blocking.py", line 2056, in upload_artifact_from_buffer
    wandb.log_artifact(artifact)
  File "/home/mahin-sanklecha/.local/lib/python3.10/site-packages/wandb/sdk/wandb_run.py", line 399, in wrapper
    return func(self, *args, **kwargs)
  File "/home/mahin-sanklecha/.local/lib/python3.10/site-packages/wandb/sdk/wandb_run.py", line 457, in wrapper_fn
    return func(self, *args, **kwargs)
  File "/home/mahin-sanklecha/.local/lib/python3.10/site-packages/wandb/sdk/wandb_run.py", line 444, in wrapper
    return func(self, *args, **kwargs)
  File "/home/mahin-sanklecha/.local/lib/python3.10/site-packages/wandb/sdk/wandb_run.py", line 3159, in log_artifact
    return self._log_artifact(
  File "/home/mahin-sanklecha/.local/lib/python3.10/site-packages/wandb/sdk/wandb_run.py", line 3310, in _log_artifact
    self._assert_can_log_artifact(artifact)
  File "/home/mahin-sanklecha/.local/lib/python3.10/site-packages/wandb/sdk/wandb_run.py", line 3358, in _assert_can_log_artifact
    public_api = self._public_api()
  File "/home/mahin-sanklecha/.local/lib/python3.10/site-packages/wandb/sdk/wandb_run.py", line 3351, in _public_api
    return public.Api(overrides)
  File "/home/mahin-sanklecha/.local/lib/python3.10/site-packages/wandb/apis/public/api.py", line 352, in __init__
    self._configure_sentry()
  File "/home/mahin-sanklecha/.local/lib/python3.10/site-packages/wandb/apis/public/api.py", line 356, in _configure_sentry
    viewer = self.viewer
  File "/home/mahin-sanklecha/.local/lib/python3.10/site-packages/wandb/apis/public/api.py", line 780, in viewer
    viewer = self._client.execute(self.VIEWER_QUERY).get("viewer")
  File "/home/mahin-sanklecha/.local/lib/python3.10/site-packages/wandb/sdk/lib/retry.py", line 211, in wrapped_fn
    return retrier(*args, **kargs)
  File "/home/mahin-sanklecha/.local/lib/python3.10/site-packages/wandb/sdk/lib/retry.py", line 134, in __call__
    result = self._call_fn(*args, **kwargs)
  File "/home/mahin-sanklecha/.local/lib/python3.10/site-packages/wandb/apis/public/api.py", line 116, in execute
    return self._client.execute(*args, **kwargs)
  File "/home/mahin-sanklecha/.local/lib/python3.10/site-packages/wandb/vendor/gql-0.2.0/wandb_gql/client.py", line 52, in execute
    result = self._get_result(document, *args, **kwargs)
  File "/home/mahin-sanklecha/.local/lib/python3.10/site-packages/wandb/vendor/gql-0.2.0/wandb_gql/client.py", line 60, in _get_result
    return self.transport.execute(document, *args, **kwargs)
  File "/home/mahin-sanklecha/.local/lib/python3.10/site-packages/wandb/sdk/lib/gql_request.py", line 58, in execute
    request = self.session.post(self.url, **post_args)
  File "/home/mahin-sanklecha/.local/lib/python3.10/site-packages/requests/sessions.py", line 637, in post
    return self.request("POST", url, data=data, json=json, **kwargs)
  File "/home/mahin-sanklecha/.local/lib/python3.10/site-packages/requests/sessions.py", line 589, in request
    resp = self.send(prep, **send_kwargs)
  File "/home/mahin-sanklecha/.local/lib/python3.10/site-packages/requests/sessions.py", line 703, in send
    r = adapter.send(request, **kwargs)
  File "/home/mahin-sanklecha/.local/lib/python3.10/site-packages/requests/adapters.py", line 644, in send
    resp = conn.urlopen(
  File "/home/mahin-sanklecha/.local/lib/python3.10/site-packages/urllib3/connectionpool.py", line 787, in urlopen
    response = self._make_request(
  File "/home/mahin-sanklecha/.local/lib/python3.10/site-packages/urllib3/connectionpool.py", line 464, in _make_request
    self._validate_conn(conn)
  File "/home/mahin-sanklecha/.local/lib/python3.10/site-packages/urllib3/connectionpool.py", line 1093, in _validate_conn
    conn.connect()
  File "/home/mahin-sanklecha/.local/lib/python3.10/site-packages/urllib3/connection.py", line 753, in connect
    self.sock = sock = self._new_conn()
  File "/home/mahin-sanklecha/.local/lib/python3.10/site-packages/urllib3/connection.py", line 198, in _new_conn
    sock = connection.create_connection(
  File "/home/mahin-sanklecha/.local/lib/python3.10/site-packages/urllib3/util/connection.py", line 60, in create_connection
    for res in socket.getaddrinfo(host, port, family, socket.SOCK_STREAM):
  File "/usr/lib/python3.10/socket.py", line 955, in getaddrinfo
    for res in _socket.getaddrinfo(host, port, family, type, proto, flags):
KeyboardInterrupt
Exception ignored in atexit callback: <function _start_and_connect_service.<locals>.teardown_atexit at 0x78ef701d9240>
Traceback (most recent call last):
  File "/home/mahin-sanklecha/.local/lib/python3.10/site-packages/wandb/sdk/lib/service/service_connection.py", line 54, in teardown_atexit
    conn.teardown(hooks.exit_code)
  File "/home/mahin-sanklecha/.local/lib/python3.10/site-packages/wandb/sdk/lib/service/service_connection.py", line 182, in teardown
    self._router.join()
  File "/home/mahin-sanklecha/.local/lib/python3.10/site-packages/wandb/sdk/interface/router.py", line 75, in join
    self._thread.join()
  File "/usr/lib/python3.10/threading.py", line 1096, in join
    self._wait_for_tstate_lock()
  File "/usr/lib/python3.10/threading.py", line 1116, in _wait_for_tstate_lock
    if lock.acquire(block, timeout):
KeyboardInterrupt:
